Workbook

Sheet Sheet1
A1: Nest_box_ID | B1: Breeding_season | C1: Breeding_attempt | D1: Female_c_band | E1: Male_c_band | F1: First_egg_lay_date | G1: Number_eggs_laid | H1: Incubation_start_date | I1: Hatch_date | J1: First_egg_to_incub_start_days | K1: Incub_start_to_hatch_length_days | L1: Laying_gap_presence | M1: Column1
A2: AB/1 | B2: 2019/2020 | C2: 1 | D2: CP12909 | E2: N/A | F2: 43789 | G2: 4 | H2: 43792 | I2: 43807 | J2: =Table1[[#This Row],[Incubation_start_date]]-Table1[[#This Row],[First_egg_lay_date]] -> 3 | K2: =Table1[[#This Row],[Hatch_date]]-Table1[[#This Row],[Incubation_start_date]] -> 15 | L2: N/A
A3: AB/3 | B3: 2019/2020 | C3: 1 | D3: CP13045 | E3: CP9218 | F3: 43779 | G3: 4 | H3: 43782 | I3: 43798 | J3: =Table1[[#This Row],[Incubation_start_date]]-Table1[[#This Row],[First_egg_lay_date]] -> 3 | K3: =Table1[[#This Row],[Hatch_date]]-Table1[[#This Row],[Incubation_start_date]] -> 16 | L3: 0
A4: B1/11 | B4: 2019/2020 | C4: 1 | D4: CP11845 | E4: CP11878 | F4: 43774 | G4: 4 | H4: 43778 | I4: 43792 | J4: =Table1[[#This Row],[Incubation_start_date]]-Table1[[#This Row],[First_egg_lay_date]] -> 4 | K4: =Table1[[#This Row],[Hatch_date]]-Table1[[#This Row],[Incubation_start_date]] -> 14 | L4: 1
A5: B1/13A | B5: 2019/2020 | C5: 1 | D5: CP11877 | E5: CP8292 | F5: 43774 | G5: 3 | H5: 43777 | I5: N/A | J5: =Table1[[#This Row],[Incubation_start_date]]-Table1[[#This Row],[First_egg_lay_date]] -> 3 | K5: N/A | L5: 1
A6: B1/13A | B6: 2019/2020 | C6: R1 | D6: CP11877 | E6: CP8292 | F6: 43809 | G6: 3 | H6: 43811 | I6: 43825 | J6: =Table1[[#This Row],[Incubation_start_date]]-Table1[[#This Row],[First_egg_lay_date]] -> 2 | K6: =Table1[[#This Row],[Hatch_date]]-Table1[[#This Row],[Incubation_start_date]] -> 14 | L6: 0
A7: B1/13B | B7: 2019/2020 | C7: 1 | D7: CP13077 | E7: C89916 | F7: 43770 | G7: 4 | H7: 43773 | I7: 43788 | J7: =Table1[[#This Row],[Incubation_start_date]]-Table1[[#This Row],[First_egg_lay_date]] -> 3 | K7: =Table1[[#This Row],[Hatch_date]]-Table1[[#This Row],[Incubation_start_date]] -> 15 | L7: 0
A8: B1/13B | B8: 2019/2020 | C8: 2 | D8: CP13077 | E8: C89916 | F8: 43827 | G8: 4 | H8: 43830 | I8: 43844 | J8: =Table1[[#This Row],[Incubation_start_date]]-Table1[[#This Row],[First_egg_lay_date]] -> 3 | K8: =Table1[[#This Row],[Hatch_date]]-Table1[[#This Row],[Incubation_start_date]] -> 14 | L8: 0
A9: B1/19 | B9: 2019/2020 | C9: 1 | D9: CP12997 | E9: CP12913 | F9: 43778 | G9: 4 | H9: 43782 | I9: 43796 | J9: =Table1[[#This Row],[Incubation_start_date]]-Table1[[#This Row],[First_egg_lay_date]] -> 4 | K9: =Table1[[#This Row],[Hatch_date]]-Table1[[#This Row],[Incubation_start_date]] -> 14 | L9: 1
A10: B1/2 | B10: 2019/2020 | C10: 1 | D10: CP13553 | E10: C75686 | F10: 43790 | G10: 4 | H10: 43793 | I10: 43808 | J10: =Table1[[#This Row],[Incubation_start_date]]-Table1[[#This Row],[First_egg_lay_date]] -> 3 | K10: =Table1[[#This Row],[Hatch_date]]-Table1[[#This Row],[Incubation_start_date]] -> 15 | L10: 0
A11: B1/23 | B11: 2019/2020 | C11: 1 | D11: C94455 | E11: C94454 | F11: 43780 | G11: 4 | H11: 43783 | I11: 43797 | J11: =Table1[[#This Row],[Incubation_start_date]]-Table1[[#This Row],[First_egg_lay_date]] -> 3 | K11: =Table1[[#This Row],[Hatch_date]]-Table1[[#This Row],[Incubation_start_date]] -> 14 | L11: N/A
A12: B1/24 | B12: 2019/2020 | C12: 1 | D12: CP13020 | E12: CP8165 | F12: 43802 | G12: 3 | H12: 43804 | I12: 43819 | J12: =Table1[[#This Row],[Incubation_start_date]]-Table1[[#This Row],[First_egg_lay_date]] -> 2 | K12: =Table1[[#This Row],[Hatch_date]]-Table1[[#This Row],[Incubation_start_date]] -> 15 | L12: 0
A13: B1/25 | B13: 2019/2020 | C13: 1 | D13: CP12961 | E13: CP13091 | F13: 43780 | G13: 4 | H13: 43783 | I13: 43797 | J13: =Table1[[#This Row],[Incubation_start_date]]-Table1[[#This Row],[First_egg_lay_date]] -> 3 | K13: =Table1[[#This Row],[Hatch_date]]-Table1[[#This Row],[Incubation_start_date]] -> 14 | L13: 0
A14: B1/26 | B14: 2019/2020 | C14: 1 | D14: CP9222 | E14: N/A | F14: 43765 | G14: 4 | H14: 43768 | I14: N/A | J14: =Table1[[#This Row],[Incubation_start_date]]-Table1[[#This Row],[First_egg_lay_date]] -> 3 | K14: N/A | L14: 0
A15: B1/27B | B15: 2019/2020 | C15: 1 | D15: CP8115 | E15: C75694 | F15: 43772 | G15: 4 | H15: 43775 | I15: 43790 | J15: =Table1[[#This Row],[Incubation_start_date]]-Table1[[#This Row],[First_egg_lay_date]] -> 3 | K15: =Table1[[#This Row],[Hatch_date]]-Table1[[#This Row],[Incubation_start_date]] -> 15 | L15: 0
A16: B1/28 | B16: 2019/2020 | C16: 1 | D16: CP13510 | E16: CP5013 | F16: 43792 | G16: 3 | H16: 43794 | I16: 43809 | J16: =Table1[[#This Row],[Incubation_start_date]]-Table1[[#This Row],[First_egg_lay_date]] -> 2 | K16: =Table1[[#This Row],[Hatch_date]]-Table1[[#This Row],[Incubation_start_date]] -> 15 | L16: 0
A17: B1/9 | B17: 2019/2020 | C17: 1 | D17: CP13444 | E17: CP8283 | F17: 43770 | G17: 4 | H17: 43773 | I17: 43788 | J17: =Table1[[#This Row],[Incubation_start_date]]-Table1[[#This Row],[First_egg_lay_date]] -> 3 | K17: =Table1[[#This Row],[Hatch_date]]-Table1[[#This Row],[Incubation_start_date]] -> 15 | L17: 0
A18: B1/PA2 | B18: 2019/2020 | C18: 1 | D18: CP13563 | E18: CP13519 | F18: 43776 | G18: 3 | H18: 43778 | I18: 43792 | J18: =Table1[[#This Row],[Incubation_start_date]]-Table1[[#This Row],[First_egg_lay_date]] -> 2 | K18: =Table1[[#This Row],[Hatch_date]]-Table1[[#This Row],[Incubation_start_date]] -> 14 | L18: 0
A19: B2/11 | B19: 2019/2020 | C19: 1 | D19: CP13502 | E19: CP8217 | F19: 43777 | G19: 4 | H19: 43780 | I19: 43795 | J19: =Table1[[#This Row],[Incubation_start_date]]-Table1[[#This Row],[First_egg_lay_date]] -> 3 | K19: =Table1[[#This Row],[Hatch_date]]-Table1[[#This Row],[Incubation_start_date]] -> 15 | L19: 0
A20: B2/13 | B20: 2019/2020 | C20: R1 | D20: CP11840 | E20: CP8253 | F20: 43810 | G20: 4 | H20: 43813 | I20: 43827 | J20: =Table1[[#This Row],[Incubation_start_date]]-Table1[[#This Row],[First_egg_lay_date]] -> 3 | K20: =Table1[[#This Row],[Hatch_date]]-Table1[[#This Row],[Incubation_start_date]] -> 14 | L20: 0
A21: B2/14 | B21: 2019/2020 | C21: 1 | D21: CP11840 | E21: CP8253 | F21: 43776 | G21: 3 | H21: 43779 | I21: 43795 | J21: =Table1[[#This Row],[Incubation_start_date]]-Table1[[#This Row],[First_egg_lay_date]] -> 3 | K21: =Table1[[#This Row],[Hatch_date]]-Table1[[#This Row],[Incubation_start_date]] -> 16 | L21: 0
A22: B2/15 | B22: 2019/2020 | C22: 1 | D22: CP12933 | E22: CP13049 | F22: 43802 | G22: 4 | H22: 43805 | I22: 43819 | J22: =Table1[[#This Row],[Incubation_start_date]]-Table1[[#This Row],[First_egg_lay_date]] -> 3 | K22: =Table1[[#This Row],[Hatch_date]]-Table1[[#This Row],[Incubation_start_date]] -> 14 | L22: 0
A23: B2/4 | B23: 2019/2020 | C23: 1 | D23: CP13562 | E23: CP13073 | F23: 43812 | G23: 3 | H23: 43814 | I23: 43828 | J23: =Table1[[#This Row],[Incubation_start_date]]-Table1[[#This Row],[First_egg_lay_date]] -> 2 | K23: =Table1[[#This Row],[Hatch_date]]-Table1[[#This Row],[Incubation_start_date]] -> 14 | L23: 0
A24: B2/8 | B24: 2019/2020 | C24: 1 | D24: CP13487 | E24: CP13073 | F24: 43791 | G24: 4 | H24: 43795 | I24: N/A | J24: =Table1[[#This Row],[Incubation_start_date]]-Table1[[#This Row],[First_egg_lay_date]] -> 4 | K24: N/A | L24: 1
A25: B2/9 | B25: 2019/2020 | C25: 1 | D25: CP13419 | E25: CP11867 | F25: 43781 | G25: 3 | H25: 43783 | I25: 43797 | J25: =Table1[[#This Row],[Incubation_start_date]]-Table1[[#This Row],[First_egg_lay_date]] -> 2 | K25: =Table1[[#This Row],[Hatch_date]]-Table1[[#This Row],[Incubation_start_date]] -> 14 | L25: 0
A26: B21/1 | B26: 2019/2020 | C26: 2 | D26: CP8110 | E26: CP2746 | F26: 43823 | G26: 4 | H26: 43826 | I26: 43840 | J26: =Table1[[#This Row],[Incubation_start_date]]-Table1[[#This Row],[First_egg_lay_date]] -> 3 | K26: =Table1[[#This Row],[Hatch_date]]-Table1[[#This Row],[Incubation_start_date]] -> 14 | L26: 0
A27: B21/11 | B27: 2019/2020 | C27: 1 | D27: CP13498 | E27: CP13486 | F27: 43779 | G27: 3 | H27: 43781 | I27: 43796 | J27: =Table1[[#This Row],[Incubation_start_date]]-Table1[[#This Row],[First_egg_lay_date]] -> 2 | K27: =Table1[[#This Row],[Hatch_date]]-Table1[[#This Row],[Incubation_start_date]] -> 15 | L27: 0
A28: B21/13 | B28: 2019/2020 | C28: 1 | D28: CP13462 | E28: CP13450 | F28: 43780 | G28: 3 | H28: 43782 | I28: 43797 | J28: =Table1[[#This Row],[Incubation_start_date]]-Table1[[#This Row],[First_egg_lay_date]] -> 2 | K28: =Table1[[#This Row],[Hatch_date]]-Table1[[#This Row],[Incubation_start_date]] -> 15 | L28: 0
A29: B21/14 | B29: 2019/2020 | C29: 1 | D29: CP13068 | E29: CP13034 | F29: 43804 | G29: 4 | H29: 43807 | I29: 43822 | J29: =Table1[[#This Row],[Incubation_start_date]]-Table1[[#This Row],[First_egg_lay_date]] -> 3 | K29: =Table1[[#This Row],[Hatch_date]]-Table1[[#This Row],[Incubation_start_date]] -> 15 | L29: 0
A30: B21/2 | B30: 2019/2020 | C30: 1 | D30: CP8110 | E30: CP2746 | F30: 43772 | G30: 4 | H30: 43775 | I30: 43789 | J30: =Table1[[#This Row],[Incubation_start_date]]-Table1[[#This Row],[First_egg_lay_date]] -> 3 | K30: =Table1[[#This Row],[Hatch_date]]-Table1[[#This Row],[Incubation_start_date]] -> 14 | L30: 0
A31: B21/4 | B31: 2019/2020 | C31: 1 | D31: CP13061 | E31: CP13413 | F31: 43779 | G31: 3 | H31: 43781 | I31: 43796 | J31: =Table1[[#This Row],[Incubation_start_date]]-Table1[[#This Row],[First_egg_lay_date]] -> 2 | K31: =Table1[[#This Row],[Hatch_date]]-Table1[[#This Row],[Incubation_start_date]] -> 15 | L31: 0
A32: B21/8 | B32: 2019/2020 | C32: 1 | D32: CP13495 | E32: CP13426 | F32: 43795 | G32: 4 | H32: 43798 | I32: 43813 | J32: =Table1[[#This Row],[Incubation_start_date]]-Table1[[#This Row],[First_egg_lay_date]] -> 3 | K32: =Table1[[#This Row],[Hatch_date]]-Table1[[#This Row],[Incubation_start_date]] -> 15 | L32: 0
A33: B22/14 | B33: 2019/2020 | C33: 1 | D33: CP5035 | E33: CP8128 | F33: 43779 | G33: 5 | H33: 43783 | I33: 43797 | J33: =Table1[[#This Row],[Incubation_start_date]]-Table1[[#This Row],[First_egg_lay_date]] -> 4 | K33: =Table1[[#This Row],[Hatch_date]]-Table1[[#This Row],[Incubation_start_date]] -> 14 | L33: 0
A34: B22/1A | B34: 2019/2020 | C34: 1 | D34: CP13554 | E34: CP13499 | F34: 43789 | G34: 4 | H34: 43792 | I34: 43806 | J34: =Table1[[#This Row],[Incubation_start_date]]-Table1[[#This Row],[First_egg_lay_date]] -> 3 | K34: =Table1[[#This Row],[Hatch_date]]-Table1[[#This Row],[Incubation_start_date]] -> 14 | L34: 0
A35: B22/2 | B35: 2019/2020 | C35: 1 | D35: CP13521 | E35: CP8137 | F35: 43775 | G35: 1 | H35: 43775 | I35: N/A | J35: =Table1[[#This Row],[Incubation_start_date]]-Table1[[#This Row],[First_egg_lay_date]] -> 0 | K35: N/A | L35: 0
A36: B22/2 | B36: 2019/2020 | C36: R1 | D36: CP13521 | E36: CP8137 | F36: 43793 | G36: 4 | H36: 43796 | I36: 43810 | J36: =Table1[[#This Row],[Incubation_start_date]]-Table1[[#This Row],[First_egg_lay_date]] -> 3 | K36: =Table1[[#This Row],[Hatch_date]]-Table1[[#This Row],[Incubation_start_date]] -> 14 | L36: 0
A37: B22/21 | B37: 2019/2020 | C37: 1 | D37: CP13055 | E37: CP2724 | F37: 43775 | G37: 1 | H37: 43775 | I37: N/A | J37: =Table1[[#This Row],[Incubation_start_date]]-Table1[[#This Row],[First_egg_lay_date]] -> 0 | K37: N/A | L37: 0
A38: B22/22 | B38: 2019/2020 | C38: R1 | D38: CP13055 | E38: CP13428 | F38: 43809 | G38: 5 | H38: 43813 | I38: 43827 | J38: =Table1[[#This Row],[Incubation_start_date]]-Table1[[#This Row],[First_egg_lay_date]] -> 4 | K38: =Table1[[#This Row],[Hatch_date]]-Table1[[#This Row],[Incubation_start_date]] -> 14 | L38: 0
A39: B22/23 | B39: 2019/2020 | C39: 1 | D39: CP12980 | E39: CP9280 | F39: 43801 | G39: 5 | H39: 43805 | I39: 43819 | J39: =Table1[[#This Row],[Incubation_start_date]]-Table1[[#This Row],[First_egg_lay_date]] -> 4 | K39: =Table1[[#This Row],[Hatch_date]]-Table1[[#This Row],[Incubation_start_date]] -> 14 | L39: 0
A40: B22/25 | B40: 2019/2020 | C40: 1 | D40: CP13437 | E40: CP11880 | F40: 43771 | G40: 4 | H40: 43774 | I40: 43789 | J40: =Table1[[#This Row],[Incubation_start_date]]-Table1[[#This Row],[First_egg_lay_date]] -> 3 | K40: =Table1[[#This Row],[Hatch_date]]-Table1[[#This Row],[Incubation_start_date]] -> 15 | L40: 0
...

Sheet Incub_summary
A1: Breeding_season | B1: Nest | C1: Day_of_inc | D1: Obs_date | E1: Total_on_bout_duration | F1: Total_off_bout_duration | G1: On_bout_frequency | H1: Off_bout_frequency

Sheet Desc_stats
A1: Variable | B1: Visual | D1: Descriptive statistics
B2: Histogram | C2: Bar plot | D2: Mean | E2: Median | F2: Mode | G2: Range | H2: SD | I2: Variance
A3: No_eggs_laid | B3: N/A | C3: Normal distribution | D3: 3.821053 | E3: 4 | F3: 4 | G3: =(5-1) -> 4 | H3: 0.6681022 | I3: 0.4463606
A4: Laying_time_days | B4: N/A | C4: Normal distribution | D4: 2.946809 | E4: 3 | F4: 3 | G4: =(4-2) -> 2 | H4: 0.7385982 | I4: 0.5455273
A5: Inc_period_days | B5: N/A | C5: Skew towards 14 days | D5: 14.43182 | E5: 14 | F5: 14 | G5: =(16-14) -> 2 | H5: 0.5832027 | I5: 0.3401254
A6: Laying_gap_pres | B6: N/A | C6: Skew towards 0 laying gap | F6: 0
A8: First_egg_lay_date | B8: Left-skewed | C8: N/A
A9: Incub_start_date | B9: Left-skewed | C9: N/A
A10: Hatch_date | B10: Left-skewed | C10: N/A
A11: Obs_length_minutes | B11: N/A | C11: Normal distribution
A12: Obs_day_of_inc
A13: On_bout_duration_seconds | B13: Left-skewed, one clear mode | C13: N/A
A14: Off_bout_duration_seconds | B14: Extremely left-skewed, bimodal | C14: N/A
A15: On_bout_proportion
A16: Off_bout_proportion
A18: lay_av_temp_celcius
A19: obs_niwa_tmin_celcius | B19: right-skewed; bimodal | C19: N/A | D19: 13.18889 | E19: 13.55 | F19: ~15 | G19: 12.1 | H19: 2.937713 | I19: 8.630155
A20: obs_niwa_tmax_celcius | B20: slightly left-skewed; biomodal | C20: N/A | D20: 20.385 | E20: 20.85 | F20: ~16;~21 | G20: 14.2 | H20: 3.518244 | I20: 12.37804
A21: obs_niwa_av_temp_celcius | B21: normal; multimodal | C21: N/A | D21: 16.36672 | E21: 16.735 | F21: ~14'~18 | G21: 12.1 | H21: 3.140243 | I21: 9.861125
A23: ibutton_temp_nest | B23: slightly left-skewed; symetrical | C23: N/A | D23: 17.76731 | E23: 17.596 | F23: ~16 | G23: 34.97 | H23: 3.151104 | I23: 9.929459
A24: ibutton_start_date | B24: N/A | C24: Left-skewed, U-shaped distribution, bimodal | F24: ~15/11/19; ~21/11/19 | G24: 52 days
A25: ibutton_end_date | B25: N/A | C25: Heavily right-skewed distribution | F25: ~26/11/19; 27/11/19 | G25: 60 days
A26: ibutton_start_time | B26: N/A | C26: Flat plot, no mode | F26: N/A | G26: 1213 minutes
A27: ibutton_end_time | B27: N/A | C27: U-shaped distribution, no mode | F27: N/A | G27: 1313 minutes
A28: ibutton_location
A29: Habitat_type

Sheet 19-20_niwa_temp_data
A1: station | B1: date | C1: time | D1: tmax | E1: period | F1: tmin | G1: av_temp
A2: Tiri Tiri Lighthouse | B2: 43709 | C2: 9 | D2: 15 | E2: 24 | F2: 8.9 | G2: =GEOMEAN(D2,F2) -> 11.55422
A3: Tiri Tiri Lighthouse | B3: 43710 | C3: 9 | D3: 14.5 | E3: 24 | F3: 9.4 | G3: =GEOMEAN(D3,F3) -> 11.674759
A4: Tiri Tiri Lighthouse | B4: 43711 | C4: 9 | D4: 14.6 | E4: 24 | F4: 10.4 | G4: =GEOMEAN(D4,F4) -> 12.322337
A5: Tiri Tiri Lighthouse | B5: 43712 | C5: 9 | D5: 15.2 | E5: 24 | F5: 12.2 | G5: =GEOMEAN(D5,F5) -> 13.617636
A6: Tiri Tiri Lighthouse | B6: 43713 | C6: 9 | D6: 15.8 | E6: 24 | F6: 12.2 | G6: =GEOMEAN(D6,F6) -> 13.883804
A7: Tiri Tiri Lighthouse | B7: 43714 | C7: 9 | D7: 15.9 | E7: 24 | F7: 10.2 | G7: =GEOMEAN(D7,F7) -> 12.734991
A8: Tiri Tiri Lighthouse | B8: 43715 | C8: 9 | D8: 14.7 | E8: 24 | F8: 7.9 | G8: =GEOMEAN(D8,F8) -> 10.776363
A9: Tiri Tiri Lighthouse | B9: 43716 | C9: 9 | D9: 15.4 | E9: 24 | F9: 8.9 | G9: =GEOMEAN(D9,F9) -> 11.707263
A10: Tiri Tiri Lighthouse | B10: 43717 | C10: 9 | D10: 17.7 | E10: 24 | F10: 10.4 | G10: =GEOMEAN(D10,F10) -> 13.567608
A11: Tiri Tiri Lighthouse | B11: 43718 | C11: 9 | D11: 17.8 | E11: 24 | F11: 10.4 | G11: =GEOMEAN(D11,F11) -> 13.605881
A12: Tiri Tiri Lighthouse | B12: 43719 | C12: 9 | D12: 17.8 | E12: 24 | F12: 8.9 | G12: =GEOMEAN(D12,F12) -> 12.586501
A13: Tiri Tiri Lighthouse | B13: 43720 | C13: 9 | D13: 14.8 | E13: 24 | F13: 9.2 | G13: =GEOMEAN(D13,F13) -> 11.668762
... A181: Tiri Tiri Lighthouse | B181: 43890 | C181: 8 | D181: 25 | E181: 24 | F181: 17.6 | G181: =GEOMEAN(D181,F181) -> 20.976177

Sheet 19-20_female_cohort
A1: Nest box ID | B1: Success | C1: Clutch | D1: Clutch size | E1: Chicks hatched | F1: Chicks banded | G1: Chicks fledged | H1: Female cohort | I1: Female C-band
A2: AB/1 | B2: F | C2: 1 | D2: 4 | E2: 3 | F2: 0 | G2: 0 | H2: 2017/2018 | I2: CP12909
A3: AB/3 | B3: S | C3: 1 | D3: 4 | E3: 3 | F3: 3 | G3: 3 | H3: 2018/2019 | I3: CP13045
A4: B1/11 | B4: S | C4: 1 | D4: 4 | E4: 4 | F4: 4 | G4: 4 | H4: 2016/2017 | I4: CP11845
A5: B1/13A | B5: F | C5: 1 | D5: 3 | E5: 0 | F5: 0 | G5: 0 | H5: 2016/2017 | I5: CP11877
A6: B1/13A | B6: S | C6: R1 | D6: 3 | E6: 2 | F6: 2 | G6: 2 | H6: 2016/2017 | I6: CP11877
A7: B1/13B | B7: S | C7: 1 | D7: 4 | E7: 3 | F7: 3 | G7: 3 | H7: 2018/2019 | I7: CP13077
A8: B1/13B | B8: F | C8: 2 | D8: 4 | E8: 1 | F8: 0 | G8: 0 | H8: 2018/2019 | I8: CP13077
A9: B1/19 | B9: S | C9: 1 | D9: 4 | E9: 3 | F9: 3 | G9: 3 | H9: 2017/2018 | I9: CP12997
A10: B1/2 | B10: S | C10: 1 | D10: 4 | E10: 4 | F10: 4 | G10: 4 | H10: 2018/2019 | I10: CP13553
A11: B1/23 | B11: S | C11: 1 | D11: 4 | E11: 4 | F11: 3 | G11: 3 | H11: 2013/2014 | I11: C94455
A12: B1/24 | B12: S | C12: 1 | D12: 3 | E12: 3 | F12: 3 | G12: 3 | H12: 2017/2018 | I12: CP13020
A13: B1/25 | B13: S | C13: 1 | D13: 4 | E13: 4 | F13: 2 | G13: 2 | H13: 2017/2018 | I13: CP12961
A14: B1/26 | B14: F | C14: 1 | D14: 4 | E14: 0 | F14: 0 | G14: 0 | H14: 2015/2016 | I14: CP9222
A15: B1/27B | B15: S | C15: 1 | D15: 4 | E15: 4 | F15: 3 | G15: 3 | H15: 2014/2015 | I15: CP8115
A16: B1/28 | B16: S | C16: 1 | D16: 3 | E16: 1 | F16: 1 | G16: 1 | H16: 2018/2019 | I16: CP13510
A17: B1/9 | B17: S | C17: 1 | D17: 4 | E17: 2 | F17: 2 | G17: 2 | H17: 2018/2019 | I17: CP13444
A18: B1/PA2 | B18: S | C18: 1 | D18: 3 | E18: 3 | F18: 2 | G18: 2 | H18: 2018/2019 | I18: CP13563
A19: B2/11 | B19: S | C19: 1 | D19: 4 | E19: 4 | F19: 4 | G19: 4 | H19: 2018/2019 | I19: CP13502
A20: B2/13 | B20: S | C20: R1 | D20: 4 | E20: 2 | F20: 2 | G20: 2 | H20: 2016/2017 | I20: CP11840
A21: B2/14 | B21: F | C21: 1 | D21: 3 | E21: 2 | F21: 0 | G21: 0 | H21: 2016/2017 | I21: CP11840
A22: B2/15 | B22: S | C22: 1 | D22: 4 | E22: 4 | F22: 3 | G22: 3 | H22: 2017/2018 | I22: CP12933
A23: B2/4 | B23: F | C23: 1 | D23: 3 | E23: 2 | F23: 0 | G23: 0 | H23: 2018/2019 | I23: CP13562
A24: B2/8 | B24: F | C24: 1 | D24: 4 | E24: 0 | F24: 0 | G24: 0 | H24: 2018/2019 | I24: CP13487
A25: B2/9 | B25: S | C25: 1 | D25: 3 | E25: 3 | F25: 3 | G25: 3 | H25: 2018/2019 | I25: CP13419
A26: B21/1 | B26: S | C26: 2 | D26: 4 | E26: 3 | F26: 1 | G26: 1 | H26: 2014/2015 | I26: CP8110
A27: B21/11 | B27: S | C27: 1 | D27: 3 | E27: 3 | F27: 2 | G27: 2 | H27: 2018/2019 | I27: CP13498
A28: B21/13 | B28: S | C28: 1 | D28: 3 | E28: 2 | F28: 2 | G28: 2 | H28: 2018/2019 | I28: CP13462
A29: B21/14 | B29: S | C29: 1 | D29: 4 | E29: 4 | F29: 4 | G29: 4 | H29: 2018/2019 | I29: CP13068
A30: B21/2 | B30: S | C30: 1 | D30: 4 | E30: 4 | F30: 4 | G30: 4 | H30: 2014/2015 | I30: CP8110
A31: B21/4 | B31: S | C31: 1 | D31: 3 | E31: 3 | F31: 3 | G31: 3 | H31: 2018/2019 | I31: CP13061
A32: B21/8 | B32: S | C32: 1 | D32: 4 | E32: 3 | F32: 3 | G32: 3 | H32: 2018/2019 | I32: CP13495
... A35: B22/2 | B35: F | C35: 1 | D35: 1 | E35: 0 | F35: 0 | G35: 0 | H35: 2018/2019 | I35: CP13521
A36: B22/2 | B36: S | C36: R1 | D36: 4 | E36: 3 | F36: 3 | G36: 3 | H36: 2018/2019 | I36: CP13521
A37: B22/21 | B37: F | C37: 1 | D37: 1 | E37: 0 | F37: 0 | G37: 0 | H37: 2018/2019 | I37: CP13055
A38: B22/22 | B38: S | C38: R1 | D38: 5 | E38: 4 | F38: 3 | G38: 3 | H38: 2018/2019 | I38: CP13055
A39: B22/23 | B39: S | C39: 1 | D39: 5 | E39: 5 | F39: 4 | G39: 4 | H39: 2017/2018 | I39: CP12980
A40: B22/25 | B40: F | C40: 1 | D40: 4 | E40: 2 | F40: 0 | G40: 0 | H40: 2018/2019 | I40: CP13437
A41: B22/26 | B41: S | C41: R1 | D41: 4 | E41: 2 | F41: 2 | G41: 2 | H41: 2018/2019 | I41: CP13437
A42: B22/28 | B42: S | C42: 1 | D42: 4 | E42: 2 | F42: 1 | G42: 1 | H42: 2017/2018 | I42: CP12941
...

Sheet Sheet2
A1: Breeding_season | B1: Nest_ID | C1: Inc_stage | D1: Day_of_inc | E1: Obs_date | F1: Start_Obs_Time | G1: End_Obs_Time | H1: Total_obs_length_minutes
A2: 2019/2020 | B2: AB/3 | C2: Middle | D2: 7 | E2: 43789 | F2: 0.43384259 | H2: 63
A3: 2019/2020 | B3: AB/3 | C3: Late | D3: 14 | E3: 43796 | F3: 0.33587963 | H3: 81.016667
A4: 2019/2020 | B4: B1/11 | C4: Early | D4: 1 | E4: 43779 | F4: 0.62599537 | H4: 69
A5: 2019/2020 | B5: B1/11 | C5: Middle | D5: 7 | E5: 43787 | F5: 0.51634259 | H5: 60
A6: 2019/2020 | B6: B1/11 | C6: Late | D6: 13 | E6: 43791 | F6: 0.47298611 | H6: 65
A7: 2019/2020 | B7: B1/13B | C7: Early | D7: 2 | E7: 43773 | F7: 0.57986111 | H7: 24.466667
A8: 2019/2020 | B8: B1/13B | C8: Early | D8: 3 | E8: 43774 | F8: 0.58078704 | H8: 113.83333
A9: 2019/2020 | B9: B1/13B | C9: Late | D9: 13 | E9: 43786 | F9: 0.56180556 | H9: 160.41667
A10: 2019/2020 | B10: B1/19 | C10: Late | D10: 13 | E10: 43795 | F10: 0.48002315 | H10: 65
A11: 2019/2020 | B11: B1/2 | C11: Early | D11: 1 | E11: 43794 | F11: 0.54236111 | H11: 67.283333
A12: 2019/2020 | B12: B1/2 | C12: Late | D12: 13 | E12: 43805 | F12: 0.59097222 | H12: 60
A13: 2019/2020 | B13: B1/24 | C13: Early | D13: 1 | E13: 43805 | F13: 0.6550463 | H13: 77
... A29: 2019/2020 | B29: B2/15 | C29: Early | D29: 1 | E29: 43806 | F29: 0.56821759 | H29: 62
A30: 2019/2020 | B30: B2/4 | C30: Early | D30: 1 | E30: 43816 | F30: 0.60295139 | G30: 0.63655093 | H30: 48
A31: 2019/2020 | B31: B2/8 | C31: Early | D31: 1 | E31: 43796 | F31: 0.53070602 | H31: 62
A32: 2019/2020 | B32: B2/9 | C32: Late | D32: 13 | E32: 43796 | F32: 0.51710648 | H32: 22
A33: 2019/2020 | B33: B21/11 | C33: Late | D33: 13 | E33: 43794 | F33: 0.42222222 | H33: 62
A34: 2019/2020 | B34: B21/14 | C34: Early | D34: 1 | E34: 43808 | F34: 0.59328704 | H34: 60
A35: 2019/2020 | B35: B21/2 | C35: Early | D35: 1 | E35: 43776 | F35: 0.50972222 | H35: 148.8
A36: 2019/2020 | B36: B21/2 | C36: Middle | D36: 7 | E36: 43782 | F36: 0.5950463 | H36: #VALUE!
A37: 2019/2020 | B37: B21/4 | C37: Early | D37: 1 | E37: 43783 | F37: 0.64280093 | H37: 34.366667
A38: 2019/2020 | B38: B21/4 | C38: Late | D38: 13 | E38: 43794 | F38: 0.46883102 | H38: 79
A39: 2019/2020 | B39: B22/1A | C39: Early | D39: 1 | E39: 43793 | F39: 0.56319444 | H39: 61
A40: 2019/2020 | B40: B22/1A | C40: Late | D40: 13 | E40: 43804 | F40: 0.46724537 | H40: 67
A41: 2019/2020 | B41: B22/2 | C41: Middle | D41: 7 | E41: 43803 | F41: 0.51778935 | H41: 150.96667
A42: 2019/2020 | B42: B22/21 | C42: Middle | D42: 7 | E42: 43782 | F42: 0.53880787 | H42: 62
A43: 2019/2020 | B43: B22/23 | C43: Early | D43: 1 | E43: 43805 | F43: 0.51490741 | H43: 73
A44: 2019/2020 | B44: B22/25 | C44: Early | D44: 1 | E44: 43774 | F44: 0.5753125 | H44: 63
A45: 2019/2020 | B45: B22/25 | C45: Early | D45: 3 | E45: 43776 | F45: 0.57430556 | H45: 60
A46: 2019/2020 | B46: B22/28 | C46: Early | D46: 1 | E46: 43806 | F46: 0.51105324 | H46: 70
A47: 2019/2020 | B47: B22/30 | C47: Early | D47: 2 | E47: 43774 | F47: 0.52291667 | H47: 60
A48: 2019/2020 | B48: B22/30 | C48: Middle | D48: 8 | E48: 43781 | F48: 0.4215162 | H48: 93
... A101: 2019/2020 | B101: WV/11 | C101: Early | D101: 1 | E101: 43791 | F101: 0.61782407 | H101: 60

Sheet Model_draft_inc_temp_data
A1: Breeding_season | B1: Nest_box_ID | C1: Female_ID | D1: Female_cohort | E1: Female_age | F1: First_egg_lay_date | G1: Lay_av_temp_celcius | H1: Clutch_size | I1: Inc_start_date | J1: Laying_gap | K1: Hatch_date | L1: Inc_period_length_days | M1: Obs_date | N1: Obs_bout_time | O1: Inc_day | P1: Total_obs_duration_minutes | Q1: Bout_type_on_off | R1: Bout_duration_seconds | S1: Obs_Niwa_daily_av_ambient_temp_celcius | T1: Lay_date_av_temp
A2: 2019/2020 | B2: AB/3 | C2: CP13045 | D2: =_xlfn.XLOOKUP(Table2[[#This Row],[Female_ID ]],'19-20_female_cohort'!I:I,'19-20_female_cohort'!H:H, "No Match") -> 2018/2019 | E2: 1 | F2: 43779 | G2: =_xlfn.XLOOKUP(Table2[[#This Row],[First_egg_lay_date]],'19-20_niwa_temp_data'!B:B,'19-20_niwa_temp_data'!G:G, "No Match") -> 17.618172 | H2: 4 | I2: 43782 | J2: =_xlfn.XLOOKUP(Table2[[#This Row],[Nest_box_ID]],Sheet1!A:A,Sheet1!L:L, "No Match") -> 0 | K2: 43798 | L2: =_xlfn.XLOOKUP(Table2[[#This Row],[Nest_box_ID]],Sheet1!A:A,Sheet1!K:K, "No Match") -> 16 | M2: 43796 | N2: 0.37913194 | O2: 14 | P2: 81.016667 | Q2: off | R2: 522 | S2: =_xlfn.XLOOKUP(Table2[[#This Row],[Obs_date]],'19-20_niwa_temp_data'!B:B,'19-20_niwa_temp_data'!G:G, "N/A") -> 17.287857 | T2: =_xlfn.XLOOKUP(Table2[[#This Row],[First_egg_lay_date]],'19-20_niwa_temp_data'!B:B,'19-20_niwa_temp_data'!G:G, "No Match") -> 17.618172
A3: 2019/2020 | B3: AB/3 | C3: CP13045 | D3: =_xlfn.XLOOKUP(Table2[[#This Row],[Female_ID ]],'19-20_female_cohort'!I:I,'19-20_female_cohort'!H:H, "No Match") -> 2018/2019 | E3: 1 | F3: 43779 | G3: =_xlfn.XLOOKUP(Table2[[#This Row],[First_egg_lay_date]],'19-20_niwa_temp_data'!B:B,'19-20_niwa_temp_data'!G:G, "No Match") -> 17.618172 | H3: 4 | I3: 43782 | J3: =_xlfn.XLOOKUP(Table2[[#This Row],[Nest_box_ID]],Sheet1!A:A,Sheet1!L:L, "No Match") -> 0 | K3: 43798 | L3: =_xlfn.XLOOKUP(Table2[[#This Row],[Nest_box_ID]],Sheet1!A:A,Sheet1!K:K, "No Match") -> 16 | M3: 43796 | N3: 0.38517361 | O3: 14 | P3: 81.016667 | Q3: off | R3: 512 | S3: =_xlfn.XLOOKUP(Table2[[#This Row],[Obs_date]],'19-20_niwa_temp_data'!B:B,'19-20_niwa_temp_data'!G:G, "N/A") -> 17.287857 | T3: =_xlfn.XLOOKUP(Table2[[#This Row],[First_egg_lay_date]],'19-20_niwa_temp_data'!B:B,'19-20_niwa_temp_data'!G:G, "No Match") -> 17.618172
A4: 2019/2020 | B4: AB/3 | C4: CP13045 | D4: =_xlfn.XLOOKUP(Table2[[#This Row],[Female_ID ]],'19-20_female_cohort'!I:I,'19-20_female_cohort'!H:H, "No Match") -> 2018/2019 | E4: 1 | F4: 43779 | G4: =_xlfn.XLOOKUP(Table2[[#This Row],[First_egg_lay_date]],'19-20_niwa_temp_data'!B:B,'19-20_niwa_temp_data'!G:G, "No Match") -> 17.618172 | H4: 4 | I4: 43782 | J4: =_xlfn.XLOOKUP(Table2[[#This Row],[Nest_box_ID]],Sheet1!A:A,Sheet1!L:L, "No Match") -> 0 | K4: 43798 | L4: =_xlfn.XLOOKUP(Table2[[#This Row],[Nest_box_ID]],Sheet1!A:A,Sheet1!K:K, "No Match") -> 16 | M4: 43796 | N4: 0.39109954 | O4: 14 | P4: 81.016667 | Q4: on | R4: 282 | S4: =_xlfn.XLOOKUP(Table2[[#This Row],[Obs_date]],'19-20_niwa_temp_data'!B:B,'19-20_niwa_temp_data'!G:G, "N/A") -> 17.287857 | T4: =_xlfn.XLOOKUP(Table2[[#This Row],[First_egg_lay_date]],'19-20_niwa_temp_data'!B:B,'19-20_niwa_temp_data'!G:G, "No Match") -> 17.618172
A5: 2019/2020 | B5: AB/3 | C5: CP13045 | D5: =_xlfn.XLOOKUP(Table2[[#This Row],[Female_ID ]],'19-20_female_cohort'!I:I,'19-20_female_cohort'!H:H, "No Match") -> 2018/2019 | E5: 1 | F5: 43779 | G5: =_xlfn.XLOOKUP(Table2[[#This Row],[First_egg_lay_date]],'19-20_niwa_temp_data'!B:B,'19-20_niwa_temp_data'!G:G, "No Match") -> 17.618172 | H5: 4 | I5: 43782 | J5: =_xlfn.XLOOKUP(Table2[[#This Row],[Nest_box_ID]],Sheet1!A:A,Sheet1!L:L, "No Match") -> 0 | K5: 43798 | L5: =_xlfn.XLOOKUP(Table2[[#This Row],[Nest_box_ID]],Sheet1!A:A,Sheet1!K:K, "No Match") -> 16 | M5: 43796 | N5: 0.39436343 | O5: 14 | P5: 81.016667 | Q5: off | R5: 248 | S5: =_xlfn.XLOOKUP(Table2[[#This Row],[Obs_date]],'19-20_niwa_temp_data'!B:B,'19-20_niwa_temp_data'!G:G, "N/A") -> 17.287857 | T5: =_xlfn.XLOOKUP(Table2[[#This Row],[First_egg_lay_date]],'19-20_niwa_temp_data'!B:B,'19-20_niwa_temp_data'!G:G, "No Match") -> 17.618172
A6: 2019/2020 | B6: AB/3 | C6: CP13045 | D6: =_xlfn.XLOOKUP(Table2[[#This Row],[Female_ID ]],'19-20_female_cohort'!I:I,'19-20_female_cohort'!H:H, "No Match") -> 2018/2019 | E6: 1 | F6: 43779 | G6: =_xlfn.XLOOKUP(Table2[[#This Row],[First_egg_lay_date]],'19-20_niwa_temp_data'!B:B,'19-20_niwa_temp_data'!G:G, "No Match") -> 17.618172 | H6: 4 | I6: 43782 | J6: =_xlfn.XLOOKUP(Table2[[#This Row],[Nest_box_ID]],Sheet1!A:A,Sheet1!L:L, "No Match") -> 0 | K6: 43798 | L6: =_xlfn.XLOOKUP(Table2[[#This Row],[Nest_box_ID]],Sheet1!A:A,Sheet1!K:K, "No Match") -> 16 | M6: 43796 | N6: 0.3972338 | O6: 14 | P6: 81.016667 | Q6: on | R6: 271 | S6: =_xlfn.XLOOKUP(Table2[[#This Row],[Obs_date]],'19-20_niwa_temp_data'!B:B,'19-20_niwa_temp_data'!G:G, "N/A") -> 17.287857 | T6: =_xlfn.XLOOKUP(Table2[[#This Row],[First_egg_lay_date]],'19-20_niwa_temp_data'!B:B,'19-20_niwa_temp_data'!G:G, "No Match") -> 17.618172
A7: 2019/2020 | B7: AB/3 | C7: CP13045 | D7: =_xlfn.XLOOKUP(Table2[[#This Row],[Female_ID ]],'19-20_female_cohort'!I:I,'19-20_female_cohort'!H:H, "No Match") -> 2018/2019 | E7: 1 | F7: 43779 | G7: =_xlfn.XLOOKUP(Table2[[#This Row],[First_egg_lay_date]],'19-20_niwa_temp_data'!B:B,'19-20_niwa_temp_data'!G:G, "No Match") -> 17.618172 | H7: 4 | I7: 43782 | J7: =_xlfn.XLOOKUP(Table2[[#This Row],[Nest_box_ID]],Sheet1!A:A,Sheet1!L:L, "No Match") -> 0 | K7: 43798 | L7: =_xlfn.XLOOKUP(Table2[[#This Row],[Nest_box_ID]],Sheet1!A:A,Sheet1!K:K, "No Match") -> 16 | M7: 43796 | N7: 0.40037037 | O7: 14 | P7: 81.016667 | Q7: off | R7: 221 | S7: =_xlfn.XLOOKUP(Table2[[#This Row],[Obs_date]],'19-20_niwa_temp_data'!B:B,'19-20_niwa_temp_data'!G:G, "N/A") -> 17.287857 | T7: =_xlfn.XLOOKUP(Table2[[#This Row],[First_egg_lay_date]],'19-20_niwa_temp_data'!B:B,'19-20_niwa_temp_data'!G:G, "No Match") -> 17.618172
A8: 2019/2020 | B8: AB/3 | C8: CP13045 | D8: =_xlfn.XLOOKUP(Table2[[#This Row],[Female_ID ]],'19-20_female_cohort'!I:I,'19-20_female_cohort'!H:H, "No Match") -> 2018/2019 | E8: 1 | F8: 43779 | G8: =_xlfn.XLOOKUP(Table2[[#This Row],[First_egg_lay_date]],'19-20_niwa_temp_data'!B:B,'19-20_niwa_temp_data'!G:G, "No Match") -> 17.618172 | H8: 4 | I8: 43782 | J8: =_xlfn.XLOOKUP(Table2[[#This Row],[Nest_box_ID]],Sheet1!A:A,Sheet1!L:L, "No Match") -> 0 | K8: 43798 | L8: =_xlfn.XLOOKUP(Table2[[#This Row],[Nest_box_ID]],Sheet1!A:A,Sheet1!K:K, "No Match") -> 16 | M8: 43796 | N8: 0.40292824 | O8: 14 | P8: 81.016667 | Q8: on | R8: 180 | S8: =_xlfn.XLOOKUP(Table2[[#This Row],[Obs_date]],'19-20_niwa_temp_data'!B:B,'19-20_niwa_temp_data'!G:G, "N/A") -> 17.287857 | T8: =_xlfn.XLOOKUP(Table2[[#This Row],[First_egg_lay_date]],'19-20_niwa_temp_data'!B:B,'19-20_niwa_temp_data'!G:G, "No Match") -> 17.618172
A9: 2019/2020 | B9: AB/3 | C9: CP13045 | D9: =_xlfn.XLOOKUP(Table2[[#This Row],[Female_ID ]],'19-20_female_cohort'!I:I,'19-20_female_cohort'!H:H, "No Match") -> 2018/2019 | E9: 1 | F9: 43779 | G9: =_xlfn.XLOOKUP(Table2[[#This Row],[First_egg_lay_date]],'19-20_niwa_temp_data'!B:B,'19-20_niwa_temp_data'!G:G, "No Match") -> 17.618172 | H9: 4 | I9: 43782 | J9: =_xlfn.XLOOKUP(Table2[[#This Row],[Nest_box_ID]],Sheet1!A:A,Sheet1!L:L, "No Match") -> 0 | K9: 43798 | L9: =_xlfn.XLOOKUP(Table2[[#This Row],[Nest_box_ID]],Sheet1!A:A,Sheet1!K:K, "No Match") -> 16 | M9: 43796 | N9: 0.40501157 | O9: 14 | P9: 81.016667 | Q9: off | R9: 367 | S9: =_xlfn.XLOOKUP(Table2[[#This Row],[Obs_date]],'19-20_niwa_temp_data'!B:B,'19-20_niwa_temp_data'!G:G, "N/A") -> 17.287857 | T9: =_xlfn.XLOOKUP(Table2[[#This Row],[First_egg_lay_date]],'19-20_niwa_temp_data'!B:B,'19-20_niwa_temp_data'!G:G, "No Match") -> 17.618172
A10: 2019/2020 | B10: AB/3 | C10: CP13045 | D10: =_xlfn.XLOOKUP(Table2[[#This Row],[Female_ID ]],'19-20_female_cohort'!I:I,'19-20_female_cohort'!H:H, "No Match") -> 2018/2019 | E10: 1 | F10: 43779 | G10: =_xlfn.XLOOKUP(Table2[[#This Row],[First_egg_lay_date]],'19-20_niwa_temp_data'!B:B,'19-20_niwa_temp_data'!G:G, "No Match") -> 17.618172 | H10: 4 | I10: 43782 | J10: =_xlfn.XLOOKUP(Table2[[#This Row],[Nest_box_ID]],Sheet1!A:A,Sheet1!L:L, "No Match") -> 0 | K10: 43798 | L10: =_xlfn.XLOOKUP(Table2[[#This Row],[Nest_box_ID]],Sheet1!A:A,Sheet1!K:K, "No Match") -> 16 | M10: 43796 | N10: 0.40925926 | O10: 14 | P10: 81.016667 | Q10: on | R10: 237 | S10: =_xlfn.XLOOKUP(Table2[[#This Row],[Obs_date]],'19-20_niwa_temp_data'!B:B,'19-20_niwa_temp_data'!G:G, "N/A") -> 17.287857 | T10: =_xlfn.XLOOKUP(Table2[[#This Row],[First_egg_lay_date]],'19-20_niwa_temp_data'!B:B,'19-20_niwa_temp_data'!G:G, "No Match") -> 17.618172
A11: 2019/2020 | B11: AB/3 | C11: CP13045 | D11: =_xlfn.XLOOKUP(Table2[[#This Row],[Female_ID ]],'19-20_female_cohort'!I:I,'19-20_female_cohort'!H:H, "No Match") -> 2018/2019 | E11: 1 | F11: 43779 | G11: =_xlfn.XLOOKUP(Table2[[#This Row],[First_egg_lay_date]],'19-20_niwa_temp_data'!B:B,'19-20_niwa_temp_data'!G:G, "No Match") -> 17.618172 | H11: 4 | I11: 43782 | J11: =_xlfn.XLOOKUP(Table2[[#This Row],[Nest_box_ID]],Sheet1!A:A,Sheet1!L:L, "No Match") -> 0 | K11: 43798 | L11: =_xlfn.XLOOKUP(Table2[[#This Row],[Nest_box_ID]],Sheet1!A:A,Sheet1!K:K, "No Match") -> 16 | M11: 43796 | N11: 0.41200231 | O11: 14 | P11: 81.016667 | Q11: off | R11: 284 | S11: =_xlfn.XLOOKUP(Table2[[#This Row],[Obs_date]],'19-20_niwa_temp_data'!B:B,'19-20_niwa_temp_data'!G:G, "N/A") -> 17.287857 | T11: =_xlfn.XLOOKUP(Table2[[#This Row],[First_egg_lay_date]],'19-20_niwa_temp_data'!B:B,'19-20_niwa_temp_data'!G:G, "No Match") -> 17.618172
A12: 2019/2020 | B12: AB/3 | C12: CP13045 | D12: =_xlfn.XLOOKUP(Table2[[#This Row],[Female_ID ]],'19-20_female_cohort'!I:I,'19-20_female_cohort'!H:H, "No Match") -> 2018/2019 | E12: 1 | F12: 43779 | G12: =_xlfn.XLOOKUP(Table2[[#This Row],[First_egg_lay_date]],'19-20_niwa_temp_data'!B:B,'19-20_niwa_temp_data'!G:G, "No Match") -> 17.618172 | H12: 4 | I12: 43782 | J12: =_xlfn.XLOOKUP(Table2[[#This Row],[Nest_box_ID]],Sheet1!A:A,Sheet1!L:L, "No Match") -> 0 | K12: 43798 | L12: =_xlfn.XLOOKUP(Table2[[#This Row],[Nest_box_ID]],Sheet1!A:A,Sheet1!K:K, "No Match") -> 16 | M12: 43796 | N12: 0.41528935 | O12: 14 | P12: 81.016667 | Q12: on | R12: 267 | S12: =_xlfn.XLOOKUP(Table2[[#This Row],[Obs_date]],'19-20_niwa_temp_data'!B:B,'19-20_niwa_temp_data'!G:G, "N/A") -> 17.287857 | T12: =_xlfn.XLOOKUP(Table2[[#This Row],[First_egg_lay_date]],'19-20_niwa_temp_data'!B:B,'19-20_niwa_temp_data'!G:G, "No Match") -> 17.618172
A13: 2019/2020 | B13: AB/3 | C13: CP13045 | D13: =_xlfn.XLOOKUP(Table2[[#This Row],[Female_ID ]],'19-20_female_cohort'!I:I,'19-20_female_cohort'!H:H, "No Match") -> 2018/2019 | E13: 1 | F13: 43779 | G13: =_xlfn.XLOOKUP(Table2[[#This Row],[First_egg_lay_date]],'19-20_niwa_temp_data'!B:B,'19-20_niwa_temp_data'!G:G, "No Match") -> 17.618172 | H13: 4 | I13: 43782 | J13: =_xlfn.XLOOKUP(Table2[[#This Row],[Nest_box_ID]],Sheet1!A:A,Sheet1!L:L, "No Match") -> 0 | K13: 43798 | L13: =_xlfn.XLOOKUP(Table2[[#This Row],[Nest_box_ID]],Sheet1!A:A,Sheet1!K:K, "No Match") -> 16 | M13: 43796 | N13: 0.41837963 | O13: 14 | P13: 81.016667 | Q13: off | R13: 208 | S13: =_xlfn.XLOOKUP(Table2[[#This Row],[Obs_date]],'19-20_niwa_temp_data'!B:B,'19-20_niwa_temp_data'!G:G, "N/A") -> 17.287857 | T13: =_xlfn.XLOOKUP(Table2[[#This Row],[First_egg_lay_date]],'19-20_niwa_temp_data'!B:B,'19-20_niwa_temp_data'!G:G, "No Match") -> 17.618172
... A19: 2019/2020 | B19: AB/3 | C19: CP13045 | D19: =_xlfn.XLOOKUP(Table2[[#This Row],[Female_ID ]],'19-20_female_cohort'!I:I,'19-20_female_cohort'!H:H, "No Match") -> 2018/2019 | E19: 1 | F19: 43779 | G19: =_xlfn.XLOOKUP(Table2[[#This Row],[First_egg_lay_date]],'19-20_niwa_temp_data'!B:B,'19-20_niwa_temp_data'!G:G, "No Match") -> 17.618172 | H19: 4 | I19: 43782 | J19: =_xlfn.XLOOKUP(Table2[[#This Row],[Nest_box_ID]],Sheet1!A:A,Sheet1!L:L, "No Match") -> 0 | K19: 43798 | L19: =_xlfn.XLOOKUP(Table2[[#This Row],[Nest_box_ID]],Sheet1!A:A,Sheet1!K:K, "No Match") -> 16 | M19: 43796 | N19: 0.43091435 | O19: 14 | P19: 81.016667 | Q19: off | R19: 387 | S19: =_xlfn.XLOOKUP(Table2[[#This Row],[Obs_date]],'19-20_niwa_temp_data'!B:B,'19-20_niwa_temp_data'!G:G, "N/A") -> 17.287857 | T19: =_xlfn.XLOOKUP(Table2[[#This Row],[First_egg_lay_date]],'19-20_niwa_temp_data'!B:B,'19-20_niwa_temp_data'!G:G, "No Match") -> 17.618172
A20: 2019/2020 | B20: AB/3 | C20: CP13045 | D20: =_xlfn.XLOOKUP(Table2[[#This Row],[Female_ID ]],'19-20_female_cohort'!I:I,'19-20_female_cohort'!H:H, "No Match") -> 2018/2019 | E20: 1 | F20: 43779 | G20: =_xlfn.XLOOKUP(Table2[[#This Row],[First_egg_lay_date]],'19-20_niwa_temp_data'!B:B,'19-20_niwa_temp_data'!G:G, "No Match") -> 17.618172 | H20: 4 | I20: 43782 | J20: =_xlfn.XLOOKUP(Table2[[#This Row],[Nest_box_ID]],Sheet1!A:A,Sheet1!L:L, "No Match") -> 0 | K20: 43798 | L20: =_xlfn.XLOOKUP(Table2[[#This Row],[Nest_box_ID]],Sheet1!A:A,Sheet1!K:K, "No Match") -> 16 | M20: 43796 | N20: 0.43539352 | O20: 14 | P20: 81.016667 | Q20: on | R20: N/A | S20: =_xlfn.XLOOKUP(Table2[[#This Row],[Obs_date]],'19-20_niwa_temp_data'!B:B,'19-20_niwa_temp_data'!G:G, "N/A") -> 17.287857 | T20: =_xlfn.XLOOKUP(Table2[[#This Row],[First_egg_lay_date]],'19-20_niwa_temp_data'!B:B,'19-20_niwa_temp_data'!G:G, "No Match") -> 17.618172
A21: 2019/2020 | B21: AB/3 | C21: CP13045 | D21: =_xlfn.XLOOKUP(Table2[[#This Row],[Female_ID ]],'19-20_female_cohort'!I:I,'19-20_female_cohort'!H:H, "No Match") -> 2018/2019 | E21: 1 | F21: 43779 | G21: =_xlfn.XLOOKUP(Table2[[#This Row],[First_egg_lay_date]],'19-20_niwa_temp_data'!B:B,'19-20_niwa_temp_data'!G:G, "No Match") -> 17.618172 | H21: 4 | I21: 43782 | J21: =_xlfn.XLOOKUP(Table2[[#This Row],[Nest_box_ID]],Sheet1!A:A,Sheet1!L:L, "No Match") -> 0 | K21: 43798 | L21: =_xlfn.XLOOKUP(Table2[[#This Row],[Nest_box_ID]],Sheet1!A:A,Sheet1!K:K, "No Match") -> 16 | M21: 43789 | N21: 0.43384259 | O21: 7 | P21: 63 | Q21: off | R21: 272 | S21: =_xlfn.XLOOKUP(Table2[[#This Row],[Obs_date]],'19-20_niwa_temp_data'!B:B,'19-20_niwa_temp_data'!G:G, "N/A") -> 13.516656 | T21: =_xlfn.XLOOKUP(Table2[[#This Row],[First_egg_lay_date]],'19-20_niwa_temp_data'!B:B,'19-20_niwa_temp_data'!G:G, "No Match") -> 17.618172
A22: 2019/2020 | B22: AB/3 | C22: CP13045 | D22: =_xlfn.XLOOKUP(Table2[[#This Row],[Female_ID ]],'19-20_female_cohort'!I:I,'19-20_female_cohort'!H:H, "No Match") -> 2018/2019 | E22: 1 | F22: 43779 | G22: =_xlfn.XLOOKUP(Table2[[#This Row],[First_egg_lay_date]],'19-20_niwa_temp_data'!B:B,'19-20_niwa_temp_data'!G:G, "No Match") -> 17.618172 | H22: 4 | I22: 43782 | J22: =_xlfn.XLOOKUP(Table2[[#This Row],[Nest_box_ID]],Sheet1!A:A,Sheet1!L:L, "No Match") -> 0 | K22: 43798 | L22: =_xlfn.XLOOKUP(Table2[[#This Row],[Nest_box_ID]],Sheet1!A:A,Sheet1!K:K, "No Match") -> 16 | M22: 43789 | N22: 0.43699074 | O22: 7 | P22: 63 | Q22: on | R22: 402 | S22: =_xlfn.XLOOKUP(Table2[[#This Row],[Obs_date]],'19-20_niwa_temp_data'!B:B,'19-20_niwa_temp_data'!G:G, "N/A") -> 13.516656 | T22: =_xlfn.XLOOKUP(Table2[[#This Row],[First_egg_lay_date]],'19-20_niwa_temp_data'!B:B,'19-20_niwa_temp_data'!G:G, "No Match") -> 17.618172
A23: 2019/2020 | B23: AB/3 | C23: CP13045 | D23: =_xlfn.XLOOKUP(Table2[[#This Row],[Female_ID ]],'19-20_female_cohort'!I:I,'19-20_female_cohort'!H:H, "No Match") -> 2018/2019 | E23: 1 | F23: 43779 | G23: =_xlfn.XLOOKUP(Table2[[#This Row],[First_egg_lay_date]],'19-20_niwa_temp_data'!B:B,'19-20_niwa_temp_data'!G:G, "No Match") -> 17.618172 | H23: 4 | I23: 43782 | J23: =_xlfn.XLOOKUP(Table2[[#This Row],[Nest_box_ID]],Sheet1!A:A,Sheet1!L:L, "No Match") -> 0 | K23: 43798 | L23: =_xlfn.XLOOKUP(Table2[[#This Row],[Nest_box_ID]],Sheet1!A:A,Sheet1!K:K, "No Match") -> 16 | M23: 43789 | N23: 0.44164352 | O23: 7 | P23: 63 | Q23: off | R23: N/A | S23: =_xlfn.XLOOKUP(Table2[[#This Row],[Obs_date]],'19-20_niwa_temp_data'!B:B,'19-20_niwa_temp_data'!G:G, "N/A") -> 13.516656 | T23: =_xlfn.XLOOKUP(Table2[[#This Row],[First_egg_lay_date]],'19-20_niwa_temp_data'!B:B,'19-20_niwa_temp_data'!G:G, "No Match") -> 17.618172
A24: 2019/2020 | B24: AB/3 | C24: CP13045 | D24: =_xlfn.XLOOKUP(Table2[[#This Row],[Female_ID ]],'19-20_female_cohort'!I:I,'19-20_female_cohort'!H:H, "No Match") -> 2018/2019 | E24: 1 | F24: 43779 | G24: =_xlfn.XLOOKUP(Table2[[#This Row],[First_egg_lay_date]],'19-20_niwa_temp_data'!B:B,'19-20_niwa_temp_data'!G:G, "No Match") -> 17.618172 | H24: 4 | I24: 43782 | J24: =_xlfn.XLOOKUP(Table2[[#This Row],[Nest_box_ID]],Sheet1!A:A,Sheet1!L:L, "No Match") -> 0 | K24: 43798 | L24: =_xlfn.XLOOKUP(Table2[[#This Row],[Nest_box_ID]],Sheet1!A:A,Sheet1!K:K, "No Match") -> 16 | M24: 43796 | N24: 0.33587963 | O24: 14 | P24: 81.016667 | Q24: off | R24: 344 | S24: =_xlfn.XLOOKUP(Table2[[#This Row],[Obs_date]],'19-20_niwa_temp_data'!B:B,'19-20_niwa_temp_data'!G:G, "N/A") -> 17.287857 | T24: =_xlfn.XLOOKUP(Table2[[#This Row],[First_egg_lay_date]],'19-20_niwa_temp_data'!B:B,'19-20_niwa_temp_data'!G:G, "No Match") -> 17.618172
A25: 2019/2020 | B25: AB/3 | C25: CP13045 | D25: =_xlfn.XLOOKUP(Table2[[#This Row],[Female_ID ]],'19-20_female_cohort'!I:I,'19-20_female_cohort'!H:H, "No Match") -> 2018/2019 | E25: 1 | F25: 43779 | G25: =_xlfn.XLOOKUP(Table2[[#This Row],[First_egg_lay_date]],'19-20_niwa_temp_data'!B:B,'19-20_niwa_temp_data'!G:G, "No Match") -> 17.618172 | H25: 4 | I25: 43782 | J25: =_xlfn.XLOOKUP(Table2[[#This Row],[Nest_box_ID]],Sheet1!A:A,Sheet1!L:L, "No Match") -> 0 | K25: 43798 | L25: =_xlfn.XLOOKUP(Table2[[#This Row],[Nest_box_ID]],Sheet1!A:A,Sheet1!K:K, "No Match") -> 16 | M25: 43796 | N25: 0.33986111 | O25: 14 | P25: 81.016667 | Q25: on | R25: 437 | S25: =_xlfn.XLOOKUP(Table2[[#This Row],[Obs_date]],'19-20_niwa_temp_data'!B:B,'19-20_niwa_temp_data'!G:G, "N/A") -> 17.287857 | T25: =_xlfn.XLOOKUP(Table2[[#This Row],[First_egg_lay_date]],'19-20_niwa_temp_data'!B:B,'19-20_niwa_temp_data'!G:G, "No Match") -> 17.618172
A26: 2019/2020 | B26: AB/3 | C26: CP13045 | D26: =_xlfn.XLOOKUP(Table2[[#This Row],[Female_ID ]],'19-20_female_cohort'!I:I,'19-20_female_cohort'!H:H, "No Match") -> 2018/2019 | E26: 1 | F26: 43779 | G26: =_xlfn.XLOOKUP(Table2[[#This Row],[First_egg_lay_date]],'19-20_niwa_temp_data'!B:B,'19-20_niwa_temp_data'!G:G, "No Match") -> 17.618172 | H26: 4 | I26: 43782 | J26: =_xlfn.XLOOKUP(Table2[[#This Row],[Nest_box_ID]],Sheet1!A:A,Sheet1!L:L, "No Match") -> 0 | K26: 43798 | L26: =_xlfn.XLOOKUP(Table2[[#This Row],[Nest_box_ID]],Sheet1!A:A,Sheet1!K:K, "No Match") -> 16 | M26: 43796 | N26: 0.34491898 | O26: 14 | P26: 81.016667 | Q26: off | R26: 279 | S26: =_xlfn.XLOOKUP(Table2[[#This Row],[Obs_date]],'19-20_niwa_temp_data'!B:B,'19-20_niwa_temp_data'!G:G, "N/A") -> 17.287857 | T26: =_xlfn.XLOOKUP(Table2[[#This Row],[First_egg_lay_date]],'19-20_niwa_temp_data'!B:B,'19-20_niwa_temp_data'!G:G, "No Match") -> 17.618172
A27: 2019/2020 | B27: AB/3 | C27: CP13045 | D27: =_xlfn.XLOOKUP(Table2[[#This Row],[Female_ID ]],'19-20_female_cohort'!I:I,'19-20_female_cohort'!H:H, "No Match") -> 2018/2019 | E27: 1 | F27: 43779 | G27: =_xlfn.XLOOKUP(Table2[[#This Row],[First_egg_lay_date]],'19-20_niwa_temp_data'!B:B,'19-20_niwa_temp_data'!G:G, "No Match") -> 17.618172 | H27: 4 | I27: 43782 | J27: =_xlfn.XLOOKUP(Table2[[#This Row],[Nest_box_ID]],Sheet1!A:A,Sheet1!L:L, "No Match") -> 0 | K27: 43798 | L27: =_xlfn.XLOOKUP(Table2[[#This Row],[Nest_box_ID]],Sheet1!A:A,Sheet1!K:K, "No Match") -> 16 | M27: 43796 | N27: 0.34814815 | O27: 14 | P27: 81.016667 | Q27: on | R27: 151 | S27: =_xlfn.XLOOKUP(Table2[[#This Row],[Obs_date]],'19-20_niwa_temp_data'!B:B,'19-20_niwa_temp_data'!G:G, "N/A") -> 17.287857 | T27: =_xlfn.XLOOKUP(Table2[[#This Row],[First_egg_lay_date]],'19-20_niwa_temp_data'!B:B,'19-20_niwa_temp_data'!G:G, "No Match") -> 17.618172
A28: 2019/2020 | B28: AB/3 | C28: CP13045 | D28: =_xlfn.XLOOKUP(Table2[[#This Row],[Female_ID ]],'19-20_female_cohort'!I:I,'19-20_female_cohort'!H:H, "No Match") -> 2018/2019 | E28: 1 | F28: 43779 | G28: =_xlfn.XLOOKUP(Table2[[#This Row],[First_egg_lay_date]],'19-20_niwa_temp_data'!B:B,'19-20_niwa_temp_data'!G:G, "No Match") -> 17.618172 | H28: 4 | I28: 43782 | J28: =_xlfn.XLOOKUP(Table2[[#This Row],[Nest_box_ID]],Sheet1!A:A,Sheet1!L:L, "No Match") -> 0 | K28: 43798 | L28: =_xlfn.XLOOKUP(Table2[[#This Row],[Nest_box_ID]],Sheet1!A:A,Sheet1!K:K, "No Match") -> 16 | M28: 43796 | N28: 0.34989583 | O28: 14 | P28: 81.016667 | Q28: off | R28: 230 | S28: =_xlfn.XLOOKUP(Table2[[#This Row],[Obs_date]],'19-20_niwa_temp_data'!B:B,'19-20_niwa_temp_data'!G:G, "N/A") -> 17.287857 | T28: =_xlfn.XLOOKUP(Table2[[#This Row],[First_egg_lay_date]],'19-20_niwa_temp_data'!B:B,'19-20_niwa_temp_data'!G:G, "No Match") -> 17.618172
A29: 2019/2020 | B29: AB/3 | C29: CP13045 | D29: =_xlfn.XLOOKUP(Table2[[#This Row],[Female_ID ]],'19-20_female_cohort'!I:I,'19-20_female_cohort'!H:H, "No Match") -> 2018/2019 | E29: 1 | F29: 43779 | G29: =_xlfn.XLOOKUP(Table2[[#This Row],[First_egg_lay_date]],'19-20_niwa_temp_data'!B:B,'19-20_niwa_temp_data'!G:G, "No Match") -> 17.618172 | H29: 4 | I29: 43782 | J29: =_xlfn.XLOOKUP(Table2[[#This Row],[Nest_box_ID]],Sheet1!A:A,Sheet1!L:L, "No Match") -> 0 | K29: 43798 | L29: =_xlfn.XLOOKUP(Table2[[#This Row],[Nest_box_ID]],Sheet1!A:A,Sheet1!K:K, "No Match") -> 16 | M29: 43796 | N29: 0.35255787 | O29: 14 | P29: 81.016667 | Q29: on | R29: 167 | S29: =_xlfn.XLOOKUP(Table2[[#This Row],[Obs_date]],'19-20_niwa_temp_data'!B:B,'19-20_niwa_temp_data'!G:G, "N/A") -> 17.287857 | T29: =_xlfn.XLOOKUP(Table2[[#This Row],[First_egg_lay_date]],'19-20_niwa_temp_data'!B:B,'19-20_niwa_temp_data'!G:G, "No Match") -> 17.618172
A30: 2019/2020 | B30: AB/3 | C30: CP13045 | D30: =_xlfn.XLOOKUP(Table2[[#This Row],[Female_ID ]],'19-20_female_cohort'!I:I,'19-20_female_cohort'!H:H, "No Match") -> 2018/2019 | E30: 1 | F30: 43779 | G30: =_xlfn.XLOOKUP(Table2[[#This Row],[First_egg_lay_date]],'19-20_niwa_temp_data'!B:B,'19-20_niwa_temp_data'!G:G, "No Match") -> 17.618172 | H30: 4 | I30: 43782 | J30: =_xlfn.XLOOKUP(Table2[[#This Row],[Nest_box_ID]],Sheet1!A:A,Sheet1!L:L, "No Match") -> 0 | K30: 43798 | L30: =_xlfn.XLOOKUP(Table2[[#This Row],[Nest_box_ID]],Sheet1!A:A,Sheet1!K:K, "No Match") -> 16 | M30: 43796 | N30: 0.35449074 | O30: 14 | P30: 81.016667 | Q30: off | R30: 194 | S30: =_xlfn.XLOOKUP(Table2[[#This Row],[Obs_date]],'19-20_niwa_temp_data'!B:B,'19-20_niwa_temp_data'!G:G, "N/A") -> 17.287857 | T30: =_xlfn.XLOOKUP(Table2[[#This Row],[First_egg_lay_date]],'19-20_niwa_temp_data'!B:B,'19-20_niwa_temp_data'!G:G, "No Match") -> 17.618172
A31: 2019/2020 | B31: AB/3 | C31: CP13045 | D31: =_xlfn.XLOOKUP(Table2[[#This Row],[Female_ID ]],'19-20_female_cohort'!I:I,'19-20_female_cohort'!H:H, "No Match") -> 2018/2019 | E31: 1 | F31: 43779 | G31: =_xlfn.XLOOKUP(Table2[[#This Row],[First_egg_lay_date]],'19-20_niwa_temp_data'!B:B,'19-20_niwa_temp_data'!G:G, "No Match") -> 17.618172 | H31: 4 | I31: 43782 | J31: =_xlfn.XLOOKUP(Table2[[#This Row],[Nest_box_ID]],Sheet1!A:A,Sheet1!L:L, "No Match") -> 0 | K31: 43798 | L31: =_xlfn.XLOOKUP(Table2[[#This Row],[Nest_box_ID]],Sheet1!A:A,Sheet1!K:K, "No Match") -> 16 | M31: 43796 | N31: 0.35673611 | O31: 14 | P31: 81.016667 | Q31: on | R31: 215 | S31: =_xlfn.XLOOKUP(Table2[[#This Row],[Obs_date]],'19-20_niwa_temp_data'!B:B,'19-20_niwa_temp_data'!G:G, "N/A") -> 17.287857 | T31: =_xlfn.XLOOKUP(Table2[[#This Row],[First_egg_lay_date]],'19-20_niwa_temp_data'!B:B,'19-20_niwa_temp_data'!G:G, "No Match") -> 17.618172
A32: 2019/2020 | B32: AB/3 | C32: CP13045 | D32: =_xlfn.XLOOKUP(Table2[[#This Row],[Female_ID ]],'19-20_female_cohort'!I:I,'19-20_female_cohort'!H:H, "No Match") -> 2018/2019 | E32: 1 | F32: 43779 | G32: =_xlfn.XLOOKUP(Table2[[#This Row],[First_egg_lay_date]],'19-20_niwa_temp_data'!B:B,'19-20_niwa_temp_data'!G:G, "No Match") -> 17.618172 | H32: 4 | I32: 43782 | J32: =_xlfn.XLOOKUP(Table2[[#This Row],[Nest_box_ID]],Sheet1!A:A,Sheet1!L:L, "No Match") -> 0 | K32: 43798 | L32: =_xlfn.XLOOKUP(Table2[[#This Row],[Nest_box_ID]],Sheet1!A:A,Sheet1!K:K, "No Match") -> 16 | M32: 43796 | N32: 0.35922454 | O32: 14 | P32: 81.016667 | Q32: off | R32: 132 | S32: =_xlfn.XLOOKUP(Table2[[#This Row],[Obs_date]],'19-20_niwa_temp_data'!B:B,'19-20_niwa_temp_data'!G:G, "N/A") -> 17.287857 | T32: =_xlfn.XLOOKUP(Table2[[#This Row],[First_egg_lay_date]],'19-20_niwa_temp_data'!B:B,'19-20_niwa_temp_data'!G:G, "No Match") -> 17.618172
A33: 2019/2020 | B33: AB/3 | C33: CP13045 | D33: =_xlfn.XLOOKUP(Table2[[#This Row],[Female_ID ]],'19-20_female_cohort'!I:I,'19-20_female_cohort'!H:H, "No Match") -> 2018/2019 | E33: 1 | F33: 43779 | G33: =_xlfn.XLOOKUP(Table2[[#This Row],[First_egg_lay_date]],'19-20_niwa_temp_data'!B:B,'19-20_niwa_temp_data'!G:G, "No Match") -> 17.618172 | H33: 4 | I33: 43782 | J33: =_xlfn.XLOOKUP(Table2[[#This Row],[Nest_box_ID]],Sheet1!A:A,Sheet1!L:L, "No Match") -> 0 | K33: 43798 | L33: =_xlfn.XLOOKUP(Table2[[#This Row],[Nest_box_ID]],Sheet1!A:A,Sheet1!K:K, "No Match") -> 16 | M33: 43796 | N33: 0.36075231 | O33: 14 | P33: 81.016667 | Q33: on | R33: 157 | S33: =_xlfn.XLOOKUP(Table2[[#This Row],[Obs_date]],'19-20_niwa_temp_data'!B:B,'19-20_niwa_temp_data'!G:G, "N/A") -> 17.287857 | T33: =_xlfn.XLOOKUP(Table2[[#This Row],[First_egg_lay_date]],'19-20_niwa_temp_data'!B:B,'19-20_niwa_temp_data'!G:G, "No Match") -> 17.618172
A34: 2019/2020 | B34: AB/3 | C34: CP13045 | D34: =_xlfn.XLOOKUP(Table2[[#This Row],[Female_ID ]],'19-20_female_cohort'!I:I,'19-20_female_cohort'!H:H, "No Match") -> 2018/2019 | E34: 1 | F34: 43779 | G34: =_xlfn.XLOOKUP(Table2[[#This Row],[First_egg_lay_date]],'19-20_niwa_temp_data'!B:B,'19-20_niwa_temp_data'!G:G, "No Match") -> 17.618172 | H34: 4 | I34: 43782 | J34: =_xlfn.XLOOKUP(Table2[[#This Row],[Nest_box_ID]],Sheet1!A:A,Sheet1!L:L, "No Match") -> 0 | K34: 43798 | L34: =_xlfn.XLOOKUP(Table2[[#This Row],[Nest_box_ID]],Sheet1!A:A,Sheet1!K:K, "No Match") -> 16 | M34: 43796 | N34: 0.36256944 | O34: 14 | P34: 81.016667 | Q34: off | R34: 759 | S34: =_xlfn.XLOOKUP(Table2[[#This Row],[Obs_date]],'19-20_niwa_temp_data'!B:B,'19-20_niwa_temp_data'!G:G, "N/A") -> 17.287857 | T34: =_xlfn.XLOOKUP(Table2[[#This Row],[First_egg_lay_date]],'19-20_niwa_temp_data'!B:B,'19-20_niwa_temp_data'!G:G, "No Match") -> 17.618172
A35: 2019/2020 | B35: AB/3 | C35: CP13045 | D35: =_xlfn.XLOOKUP(Table2[[#This Row],[Female_ID ]],'19-20_female_cohort'!I:I,'19-20_female_cohort'!H:H, "No Match") -> 2018/2019 | E35: 1 | F35: 43779 | G35: =_xlfn.XLOOKUP(Table2[[#This Row],[First_egg_lay_date]],'19-20_niwa_temp_data'!B:B,'19-20_niwa_temp_data'!G:G, "No Match") -> 17.618172 | H35: 4 | I35: 43782 | J35: =_xlfn.XLOOKUP(Table2[[#This Row],[Nest_box_ID]],Sheet1!A:A,Sheet1!L:L, "No Match") -> 0 | K35: 43798 | L35: =_xlfn.XLOOKUP(Table2[[#This Row],[Nest_box_ID]],Sheet1!A:A,Sheet1!K:K, "No Match") -> 16 | M35: 43796 | N35: 0.37135417 | O35: 14 | P35: 81.016667 | Q35: off | R35: N/A | S35: =_xlfn.XLOOKUP(Table2[[#This Row],[Obs_date]],'19-20_niwa_temp_data'!B:B,'19-20_niwa_temp_data'!G:G, "N/A") -> 17.287857 | T35: =_xlfn.XLOOKUP(Table2[[#This Row],[First_egg_lay_date]],'19-20_niwa_temp_data'!B:B,'19-20_niwa_temp_data'!G:G, "No Match") -> 17.618172
A36: 2019/2020 | B36: B1/11 | C36: CP11845 | D36: =_xlfn.XLOOKUP(Table2[[#This Row],[Female_ID ]],'19-20_female_cohort'!I:I,'19-20_female_cohort'!H:H, "No Match") -> 2016/2017 | E36: 3 | F36: 43774 | G36: =_xlfn.XLOOKUP(Table2[[#This Row],[First_egg_lay_date]],'19-20_niwa_temp_data'!B:B,'19-20_niwa_temp_data'!G:G, "No Match") -> 16.129166 | H36: 4 | I36: 43778 | J36: =_xlfn.XLOOKUP(Table2[[#This Row],[Nest_box_ID]],Sheet1!A:A,Sheet1!L:L, "No Match") -> 1 | K36: 43792 | L36: =_xlfn.XLOOKUP(Table2[[#This Row],[Nest_box_ID]],Sheet1!A:A,Sheet1!K:K, "No Match") -> 14 | M36: 43779 | N36: 0.62599537 | O36: 1 | P36: 69 | Q36: off | R36: 288 | S36: =_xlfn.XLOOKUP(Table2[[#This Row],[Obs_date]],'19-20_niwa_temp_data'!B:B,'19-20_niwa_temp_data'!G:G, "N/A") -> 17.618172 | T36: =_xlfn.XLOOKUP(Table2[[#This Row],[First_egg_lay_date]],'19-20_niwa_temp_data'!B:B,'19-20_niwa_temp_data'!G:G, "No Match") -> 16.129166
A37: 2019/2020 | B37: B1/11 | C37: CP11845 | D37: =_xlfn.XLOOKUP(Table2[[#This Row],[Female_ID ]],'19-20_female_cohort'!I:I,'19-20_female_cohort'!H:H, "No Match") -> 2016/2017 | E37: 3 | F37: 43774 | G37: =_xlfn.XLOOKUP(Table2[[#This Row],[First_egg_lay_date]],'19-20_niwa_temp_data'!B:B,'19-20_niwa_temp_data'!G:G, "No Match") -> 16.129166 | H37: 4 | I37: 43778 | J37: =_xlfn.XLOOKUP(Table2[[#This Row],[Nest_box_ID]],Sheet1!A:A,Sheet1!L:L, "No Match") -> 1 | K37: 43792 | L37: =_xlfn.XLOOKUP(Table2[[#This Row],[Nest_box_ID]],Sheet1!A:A,Sheet1!K:K, "No Match") -> 14 | M37: 43779 | N37: 0.6293287 | O37: 1 | P37: 69 | Q37: on | R37: 1854 | S37: =_xlfn.XLOOKUP(Table2[[#This Row],[Obs_date]],'19-20_niwa_temp_data'!B:B,'19-20_niwa_temp_data'!G:G, "N/A") -> 17.618172 | T37: =_xlfn.XLOOKUP(Table2[[#This Row],[First_egg_lay_date]],'19-20_niwa_temp_data'!B:B,'19-20_niwa_temp_data'!G:G, "No Match") -> 16.129166
A38: 2019/2020 | B38: B1/11 | C38: CP11845 | D38: =_xlfn.XLOOKUP(Table2[[#This Row],[Female_ID ]],'19-20_female_cohort'!I:I,'19-20_female_cohort'!H:H, "No Match") -> 2016/2017 | E38: 3 | F38: 43774 | G38: =_xlfn.XLOOKUP(Table2[[#This Row],[First_egg_lay_date]],'19-20_niwa_temp_data'!B:B,'19-20_niwa_temp_data'!G:G, "No Match") -> 16.129166 | H38: 4 | I38: 43778 | J38: =_xlfn.XLOOKUP(Table2[[#This Row],[Nest_box_ID]],Sheet1!A:A,Sheet1!L:L, "No Match") -> 1 | K38: 43792 | L38: =_xlfn.XLOOKUP(Table2[[#This Row],[Nest_box_ID]],Sheet1!A:A,Sheet1!K:K, "No Match") -> 14 | M38: 43779 | N38: 0.65078704 | O38: 1 | P38: 69 | Q38: off | R38: 175 | S38: =_xlfn.XLOOKUP(Table2[[#This Row],[Obs_date]],'19-20_niwa_temp_data'!B:B,'19-20_niwa_temp_data'!G:G, "N/A") -> 17.618172 | T38: =_xlfn.XLOOKUP(Table2[[#This Row],[First_egg_lay_date]],'19-20_niwa_temp_data'!B:B,'19-20_niwa_temp_data'!G:G, "No Match") -> 16.129166
A39: 2019/2020 | B39: B1/11 | C39: CP11845 | D39: =_xlfn.XLOOKUP(Table2[[#This Row],[Female_ID ]],'19-20_female_cohort'!I:I,'19-20_female_cohort'!H:H, "No Match") -> 2016/2017 | E39: 3 | F39: 43774 | G39: =_xlfn.XLOOKUP(Table2[[#This Row],[First_egg_lay_date]],'19-20_niwa_temp_data'!B:B,'19-20_niwa_temp_data'!G:G, "No Match") -> 16.129166 | H39: 4 | I39: 43778 | J39: =_xlfn.XLOOKUP(Table2[[#This Row],[Nest_box_ID]],Sheet1!A:A,Sheet1!L:L, "No Match") -> 1 | K39: 43792 | L39: =_xlfn.XLOOKUP(Table2[[#This Row],[Nest_box_ID]],Sheet1!A:A,Sheet1!K:K, "No Match") -> 14 | M39: 43779 | N39: 0.6528125 | O39: 1 | P39: 69 | Q39: on | R39: 467 | S39: =_xlfn.XLOOKUP(Table2[[#This Row],[Obs_date]],'19-20_niwa_temp_data'!B:B,'19-20_niwa_temp_data'!G:G, "N/A") -> 17.618172 | T39: =_xlfn.XLOOKUP(Table2[[#This Row],[First_egg_lay_date]],'19-20_niwa_temp_data'!B:B,'19-20_niwa_temp_data'!G:G, "No Match") -> 16.129166
A40: 2019/2020 | B40: B1/11 | C40: CP11845 | D40: =_xlfn.XLOOKUP(Table2[[#This Row],[Female_ID ]],'19-20_female_cohort'!I:I,'19-20_female_cohort'!H:H, "No Match") -> 2016/2017 | E40: 3 | F40: 43774 | G40: =_xlfn.XLOOKUP(Table2[[#This Row],[First_egg_lay_date]],'19-20_niwa_temp_data'!B:B,'19-20_niwa_temp_data'!G:G, "No Match") -> 16.129166 | H40: 4 | I40: 43778 | J40: =_xlfn.XLOOKUP(Table2[[#This Row],[Nest_box_ID]],Sheet1!A:A,Sheet1!L:L, "No Match") -> 1 | K40: 43792 | L40: =_xlfn.XLOOKUP(Table2[[#This Row],[Nest_box_ID]],Sheet1!A:A,Sheet1!K:K, "No Match") -> 14 | M40: 43779 | N40: 0.65821759 | O40: 1 | P40: 69 | Q40: off | R40: 331 | S40: =_xlfn.XLOOKUP(Table2[[#This Row],[Obs_date]],'19-20_niwa_temp_data'!B:B,'19-20_niwa_temp_data'!G:G, "N/A") -> 17.618172 | T40: =_xlfn.XLOOKUP(Table2[[#This Row],[First_egg_lay_date]],'19-20_niwa_temp_data'!B:B,'19-20_niwa_temp_data'!G:G, "No Match") -> 16.129166
A41: 2019/2020 | B41: B1/11 | C41: CP11845 | D41: =_xlfn.XLOOKUP(Table2[[#This Row],[Female_ID ]],'19-20_female_cohort'!I:I,'19-20_female_cohort'!H:H, "No Match") -> 2016/2017 | E41: 3 | F41: 43774 | G41: =_xlfn.XLOOKUP(Table2[[#This Row],[First_egg_lay_date]],'19-20_niwa_temp_data'!B:B,'19-20_niwa_temp_data'!G:G, "No Match") -> 16.129166 | H41: 4 | I41: 43778 | J41: =_xlfn.XLOOKUP(Table2[[#This Row],[Nest_box_ID]],Sheet1!A:A,Sheet1!L:L, "No Match") -> 1 | K41: 43792 | L41: =_xlfn.XLOOKUP(Table2[[#This Row],[Nest_box_ID]],Sheet1!A:A,Sheet1!K:K, "No Match") -> 14 | M41: 43779 | N41: 0.66204861 | O41: 1 | P41: 69 | Q41: on | R41: N/A | S41: =_xlfn.XLOOKUP(Table2[[#This Row],[Obs_date]],'19-20_niwa_temp_data'!B:B,'19-20_niwa_temp_data'!G:G, "N/A") -> 17.618172 | T41: =_xlfn.XLOOKUP(Table2[[#This Row],[First_egg_lay_date]],'19-20_niwa_temp_data'!B:B,'19-20_niwa_temp_data'!G:G, "No Match") -> 16.129166
A42: 2019/2020 | B42: B1/11 | C42: CP11845 | D42: =_xlfn.XLOOKUP(Table2[[#This Row],[Female_ID ]],'19-20_female_cohort'!I:I,'19-20_female_cohort'!H:H, "No Match") -> 2016/2017 | E42: 3 | F42: 43774 | G42: =_xlfn.XLOOKUP(Table2[[#This Row],[First_egg_lay_date]],'19-20_niwa_temp_data'!B:B,'19-20_niwa_temp_data'!G:G, "No Match") -> 16.129166 | H42: 4 | I42: 43778 | J42: =_xlfn.XLOOKUP(Table2[[#This Row],[Nest_box_ID]],Sheet1!A:A,Sheet1!L:L, "No Match") -> 1 | K42: 43792 | L42: =_xlfn.XLOOKUP(Table2[[#This Row],[Nest_box_ID]],Sheet1!A:A,Sheet1!K:K, "No Match") -> 14 | M42: 43787 | N42: 0.51634259 | O42: 7 | P42: 60 | Q42: off | R42: 330 | S42: =_xlfn.XLOOKUP(Table2[[#This Row],[Obs_date]],'19-20_niwa_temp_data'!B:B,'19-20_niwa_temp_data'!G:G, "N/A") -> 16.81428 | T42: =_xlfn.XLOOKUP(Table2[[#This Row],[First_egg_lay_date]],'19-20_niwa_temp_data'!B:B,'19-20_niwa_temp_data'!G:G, "No Match") -> 16.129166
A43: 2019/2020 | B43: B1/11 | C43: CP11845 | D43: =_xlfn.XLOOKUP(Table2[[#This Row],[Female_ID ]],'19-20_female_cohort'!I:I,'19-20_female_cohort'!H:H, "No Match") -> 2016/2017 | E43: 3 | F43: 43774 | G43: =_xlfn.XLOOKUP(Table2[[#This Row],[First_egg_lay_date]],'19-20_niwa_temp_data'!B:B,'19-20_niwa_temp_data'!G:G, "No Match") -> 16.129166 | H43: 4 | I43: 43778 | J43: =_xlfn.XLOOKUP(Table2[[#This Row],[Nest_box_ID]],Sheet1!A:A,Sheet1!L:L, "No Match") -> 1 | K43: 43792 | L43: =_xlfn.XLOOKUP(Table2[[#This Row],[Nest_box_ID]],Sheet1!A:A,Sheet1!K:K, "No Match") -> 14 | M43: 43787 | N43: 0.52016204 | O43: 7 | P43: 60 | Q43: on | R43: 1341 | S43: =_xlfn.XLOOKUP(Table2[[#This Row],[Obs_date]],'19-20_niwa_temp_data'!B:B,'19-20_niwa_temp_data'!G:G, "N/A") -> 16.81428 | T43: =_xlfn.XLOOKUP(Table2[[#This Row],[First_egg_lay_date]],'19-20_niwa_temp_data'!B:B,'19-20_niwa_temp_data'!G:G, "No Match") -> 16.129166
A44: 2019/2020 | B44: B1/11 | C44: CP11845 | D44: =_xlfn.XLOOKUP(Table2[[#This Row],[Female_ID ]],'19-20_female_cohort'!I:I,'19-20_female_cohort'!H:H, "No Match") -> 2016/2017 | E44: 3 | F44: 43774 | G44: =_xlfn.XLOOKUP(Table2[[#This Row],[First_egg_lay_date]],'19-20_niwa_temp_data'!B:B,'19-20_niwa_temp_data'!G:G, "No Match") -> 16.129166 | H44: 4 | I44: 43778 | J44: =_xlfn.XLOOKUP(Table2[[#This Row],[Nest_box_ID]],Sheet1!A:A,Sheet1!L:L, "No Match") -> 1 | K44: 43792 | L44: =_xlfn.XLOOKUP(Table2[[#This Row],[Nest_box_ID]],Sheet1!A:A,Sheet1!K:K, "No Match") -> 14 | M44: 43787 | N44: 0.53568287 | O44: 7 | P44: 60 | Q44: off | R44: 352 | S44: =_xlfn.XLOOKUP(Table2[[#This Row],[Obs_date]],'19-20_niwa_temp_data'!B:B,'19-20_niwa_temp_data'!G:G, "N/A") -> 16.81428 | T44: =_xlfn.XLOOKUP(Table2[[#This Row],[First_egg_lay_date]],'19-20_niwa_temp_data'!B:B,'19-20_niwa_temp_data'!G:G, "No Match") -> 16.129166
A45: 2019/2020 | B45: B1/11 | C45: CP11845 | D45: =_xlfn.XLOOKUP(Table2[[#This Row],[Female_ID ]],'19-20_female_cohort'!I:I,'19-20_female_cohort'!H:H, "No Match") -> 2016/2017 | E45: 3 | F45: 43774 | G45: =_xlfn.XLOOKUP(Table2[[#This Row],[First_egg_lay_date]],'19-20_niwa_temp_data'!B:B,'19-20_niwa_temp_data'!G:G, "No Match") -> 16.129166 | H45: 4 | I45: 43778 | J45: =_xlfn.XLOOKUP(Table2[[#This Row],[Nest_box_ID]],Sheet1!A:A,Sheet1!L:L, "No Match") -> 1 | K45: 43792 | L45: =_xlfn.XLOOKUP(Table2[[#This Row],[Nest_box_ID]],Sheet1!A:A,Sheet1!K:K, "No Match") -> 14 | M45: 43787 | N45: 0.53975694 | O45: 7 | P45: 60 | Q45: on | R45: N/A | S45: =_xlfn.XLOOKUP(Table2[[#This Row],[Obs_date]],'19-20_niwa_temp_data'!B:B,'19-20_niwa_temp_data'!G:G, "N/A") -> 16.81428 | T45: =_xlfn.XLOOKUP(Table2[[#This Row],[First_egg_lay_date]],'19-20_niwa_temp_data'!B:B,'19-20_niwa_temp_data'!G:G, "No Match") -> 16.129166
...

Sheet Model_draft_prop_data
A1: Breeding_season | B1: Nest | C1: Female_ID | D1: Female_age | E1: Clutch_size | F1: Laying_gap | G1: Day_of_inc | H1: First_egg_lay_date | I1: Inc_start_date | J1: Obs_date | K1: Obs_start_time | L1: Obs_Av_daily_temp_celcius | M1: Inc_period_length_days | N1: Total_on_bout_duration | O1: Total_on_bout_duration_seconds | P1: Total_off_bout_duration | Q1: Total_obs_length_minutes | R1: Total_obs_length_seconds | S1: On_bout_proportion
